Workbook

Sheet Instrucciones
B2: Temario de mockinter.dev
B3: Banco de preguntas tipo test por bloque, tema y nivel. Revisa, edita y activa las que quieras que use la app.
B5: Cómo está organizado
B6: Bloques | C6: Cada puesto (Angular, React, Cloud/DevOps, Backend) tiene sus temas. Además hay bloques compartidos: «Frontend (Angular y React)», «Desarrollo» (Git y Docker, para todos los puestos técnicos) y «Común» (presentación, preguntas difíciles e inglés).
B7: Temas y niveles | C7: Cada tema tiene preguntas Junior, Mid y Senior. En la app, cada tema es una lección con tres escalones: el nivel elegido en el onboarding marca por dónde empieza el usuario, y al completar un escalón se desbloquea el siguiente.
B8: ID | C8: tema-NivelNúmero, por ejemplo ang-signals-M2. El tema sale del ID: si añades preguntas, copia el prefijo del tema.
B10: Cómo usarlo
B11: 1. Filtra | C11: En la hoja Preguntas usa los filtros por Bloque, Tema, Nivel o Tipo.
B12: 2. Revisa y edita | C12: Las celdas amarillas son editables. Cambia Estado a «Revisada» o «Descartada», y Activa a «No» para ocultar una pregunta.
B13: 3. Importa | C13: npm run import -- Temario_mockinter.xlsx genera supabase/seed.sql para cargarlo en Supabase.
B15: Tipos de pregunta
B16: Elegir respuesta | C16: Respuesta correcta + 3 incorrectas. La app las baraja.
B17: Completar frase | C17: La frase lleva ___ donde va el hueco. Respuesta correcta + 3 incorrectas.
B18: Ordenar | C18: Las piezas van en «Respuesta correcta», en orden, separadas por « | ».
B19: Código | C19: Opcional en cualquier tipo. Se muestra como bloque de código encima de las opciones (¿qué imprime?, ¿dónde está el bug?, ¿qué hace?). Respeta los saltos de línea y la indentación.
B21: Columnas extra
B22: Frase ejemplo (EN) | C22: Opcional. Se muestra tras responder: «Ejemplo de lo que podrías decir» si aciertas o «Lo que deberías decir» si fallas.
B23: Variante ES | C23: Versión de la pregunta para quien tiene la entrevista en español. Rellénala solo si el enunciado u opciones tienen frases en inglés.

Sheet Temario
A1: Bloque | B1: Tema | C1: ID del tema | D1: Junior | E1: Mid | F1: Senior | G1: Total | H1: Con código | I1: Revisadas | J1: Activas
A2: Común (todos los puestos) | B2: Presentación y método STAR | C2: com-star | D2: =COUNTIFS(Preguntas!$B$2:$B$3000,$A2,Preguntas!$C$2:$C$3000,$B2,Preguntas!$D$2:$D$3000,"Junior") -> 3 | E2: =COUNTIFS(Preguntas!$B$2:$B$3000,$A2,Preguntas!$C$2:$C$3000,$B2,Preguntas!$D$2:$D$3000,"Mid") -> 3 | F2: =COUNTIFS(Preguntas!$B$2:$B$3000,$A2,Preguntas!$C$2:$C$3000,$B2,Preguntas!$D$2:$D$3000,"Senior") -> 3 | G2: =SUM(D2:F2) -> 9 | H2: =COUNTIFS(Preguntas!$B$2:$B$3000,$A2,Preguntas!$C$2:$C$3000,$B2,Preguntas!$G$2:$G$3000,"?*") -> 0 | I2: =COUNTIFS(Preguntas!$B$2:$B$3000,$A2,Preguntas!$C$2:$C$3000,$B2,Preguntas!$O$2:$O$3000,"Revisada") -> 0 | J2: =COUNTIFS(Preguntas!$B$2:$B$3000,$A2,Preguntas!$C$2:$C$3000,$B2,Preguntas!$P$2:$P$3000,"Sí") -> 9
A3: Común (todos los puestos) | B3: Preguntas difíciles | C3: com-dificiles | D3: =COUNTIFS(Preguntas!$B$2:$B$3000,$A3,Preguntas!$C$2:$C$3000,$B3,Preguntas!$D$2:$D$3000,"Junior") -> 3 | E3: =COUNTIFS(Preguntas!$B$2:$B$3000,$A3,Preguntas!$C$2:$C$3000,$B3,Preguntas!$D$2:$D$3000,"Mid") -> 3 | F3: =COUNTIFS(Preguntas!$B$2:$B$3000,$A3,Preguntas!$C$2:$C$3000,$B3,Preguntas!$D$2:$D$3000,"Senior") -> 3 | G3: =SUM(D3:F3) -> 9 | H3: =COUNTIFS(Preguntas!$B$2:$B$3000,$A3,Preguntas!$C$2:$C$3000,$B3,Preguntas!$G$2:$G$3000,"?*") -> 0 | I3: =COUNTIFS(Preguntas!$B$2:$B$3000,$A3,Preguntas!$C$2:$C$3000,$B3,Preguntas!$O$2:$O$3000,"Revisada") -> 0 | J3: =COUNTIFS(Preguntas!$B$2:$B$3000,$A3,Preguntas!$C$2:$C$3000,$B3,Preguntas!$P$2:$P$3000,"Sí") -> 9
A4: Común (todos los puestos) | B4: Inglés de entrevista | C4: com-ingles | D4: =COUNTIFS(Preguntas!$B$2:$B$3000,$A4,Preguntas!$C$2:$C$3000,$B4,Preguntas!$D$2:$D$3000,"Junior") -> 3 | E4: =COUNTIFS(Preguntas!$B$2:$B$3000,$A4,Preguntas!$C$2:$C$3000,$B4,Preguntas!$D$2:$D$3000,"Mid") -> 3 | F4: =COUNTIFS(Preguntas!$B$2:$B$3000,$A4,Preguntas!$C$2:$C$3000,$B4,Preguntas!$D$2:$D$3000,"Senior") -> 3 | G4: =SUM(D4:F4) -> 9 | H4: =COUNTIFS(Preguntas!$B$2:$B$3000,$A4,Preguntas!$C$2:$C$3000,$B4,Preguntas!$G$2:$G$3000,"?*") -> 0 | I4: =COUNTIFS(Preguntas!$B$2:$B$3000,$A4,Preguntas!$C$2:$C$3000,$B4,Preguntas!$O$2:$O$3000,"Revisada") -> 0 | J4: =COUNTIFS(Preguntas!$B$2:$B$3000,$A4,Preguntas!$C$2:$C$3000,$B4,Preguntas!$P$2:$P$3000,"Sí") -> 9
A5: Frontend Angular | B5: Componentes y plantillas | C5: ang-components | D5: =COUNTIFS(Preguntas!$B$2:$B$3000,$A5,Preguntas!$C$2:$C$3000,$B5,Preguntas!$D$2:$D$3000,"Junior") -> 4 | E5: =COUNTIFS(Preguntas!$B$2:$B$3000,$A5,Preguntas!$C$2:$C$3000,$B5,Preguntas!$D$2:$D$3000,"Mid") -> 4 | F5: =COUNTIFS(Preguntas!$B$2:$B$3000,$A5,Preguntas!$C$2:$C$3000,$B5,Preguntas!$D$2:$D$3000,"Senior") -> 4 | G5: =SUM(D5:F5) -> 12 | H5: =COUNTIFS(Preguntas!$B$2:$B$3000,$A5,Preguntas!$C$2:$C$3000,$B5,Preguntas!$G$2:$G$3000,"?*") -> 7 | I5: =COUNTIFS(Preguntas!$B$2:$B$3000,$A5,Preguntas!$C$2:$C$3000,$B5,Preguntas!$O$2:$O$3000,"Revisada") -> 0 | J5: =COUNTIFS(Preguntas!$B$2:$B$3000,$A5,Preguntas!$C$2:$C$3000,$B5,Preguntas!$P$2:$P$3000,"Sí") -> 12
A6: Frontend Angular | B6: Signals | C6: ang-signals | D6: =COUNTIFS(Preguntas!$B$2:$B$3000,$A6,Preguntas!$C$2:$C$3000,$B6,Preguntas!$D$2:$D$3000,"Junior") -> 4 | E6: =COUNTIFS(Preguntas!$B$2:$B$3000,$A6,Preguntas!$C$2:$C$3000,$B6,Preguntas!$D$2:$D$3000,"Mid") -> 4 | F6: =COUNTIFS(Preguntas!$B$2:$B$3000,$A6,Preguntas!$C$2:$C$3000,$B6,Preguntas!$D$2:$D$3000,"Senior") -> 4 | G6: =SUM(D6:F6) -> 12 | H6: =COUNTIFS(Preguntas!$B$2:$B$3000,$A6,Preguntas!$C$2:$C$3000,$B6,Preguntas!$G$2:$G$3000,"?*") -> 4 | I6: =COUNTIFS(Preguntas!$B$2:$B$3000,$A6,Preguntas!$C$2:$C$3000,$B6,Preguntas!$O$2:$O$3000,"Revisada") -> 0 | J6: =COUNTIFS(Preguntas!$B$2:$B$3000,$A6,Preguntas!$C$2:$C$3000,$B6,Preguntas!$P$2:$P$3000,"Sí") -> 12
A7: Frontend Angular | B7: RxJS y operadores | C7: ang-rxjs | D7: =COUNTIFS(Preguntas!$B$2:$B$3000,$A7,Preguntas!$C$2:$C$3000,$B7,Preguntas!$D$2:$D$3000,"Junior") -> 4 | E7: =COUNTIFS(Preguntas!$B$2:$B$3000,$A7,Preguntas!$C$2:$C$3000,$B7,Preguntas!$D$2:$D$3000,"Mid") -> 4 | F7: =COUNTIFS(Preguntas!$B$2:$B$3000,$A7,Preguntas!$C$2:$C$3000,$B7,Preguntas!$D$2:$D$3000,"Senior") -> 4 | G7: =SUM(D7:F7) -> 12 | H7: =COUNTIFS(Preguntas!$B$2:$B$3000,$A7,Preguntas!$C$2:$C$3000,$B7,Preguntas!$G$2:$G$3000,"?*") -> 4 | I7: =COUNTIFS(Preguntas!$B$2:$B$3000,$A7,Preguntas!$C$2:$C$3000,$B7,Preguntas!$O$2:$O$3000,"Revisada") -> 0 | J7: =COUNTIFS(Preguntas!$B$2:$B$3000,$A7,Preguntas!$C$2:$C$3000,$B7,Preguntas!$P$2:$P$3000,"Sí") -> 12
A8: Frontend Angular | B8: Change detection y rendimiento | C8: ang-cd | D8: =COUNTIFS(Preguntas!$B$2:$B$3000,$A8,Preguntas!$C$2:$C$3000,$B8,Preguntas!$D$2:$D$3000,"Junior") -> 4 | E8: =COUNTIFS(Preguntas!$B$2:$B$3000,$A8,Preguntas!$C$2:$C$3000,$B8,Preguntas!$D$2:$D$3000,"Mid") -> 4 | F8: =COUNTIFS(Preguntas!$B$2:$B$3000,$A8,Preguntas!$C$2:$C$3000,$B8,Preguntas!$D$2:$D$3000,"Senior") -> 4 | G8: =SUM(D8:F8) -> 12 | H8: =COUNTIFS(Preguntas!$B$2:$B$3000,$A8,Preguntas!$C$2:$C$3000,$B8,Preguntas!$G$2:$G$3000,"?*") -> 3 | I8: =COUNTIFS(Preguntas!$B$2:$B$3000,$A8,Preguntas!$C$2:$C$3000,$B8,Preguntas!$O$2:$O$3000,"Revisada") -> 0 | J8: =COUNTIFS(Preguntas!$B$2:$B$3000,$A8,Preguntas!$C$2:$C$3000,$B8,Preguntas!$P$2:$P$3000,"Sí") -> 12
A9: Frontend Angular | B9: Formularios | C9: ang-forms | D9: =COUNTIFS(Preguntas!$B$2:$B$3000,$A9,Preguntas!$C$2:$C$3000,$B9,Preguntas!$D$2:$D$3000,"Junior") -> 4 | E9: =COUNTIFS(Preguntas!$B$2:$B$3000,$A9,Preguntas!$C$2:$C$3000,$B9,Preguntas!$D$2:$D$3000,"Mid") -> 4 | F9: =COUNTIFS(Preguntas!$B$2:$B$3000,$A9,Preguntas!$C$2:$C$3000,$B9,Preguntas!$D$2:$D$3000,"Senior") -> 4 | G9: =SUM(D9:F9) -> 12 | H9: =COUNTIFS(Preguntas!$B$2:$B$3000,$A9,Preguntas!$C$2:$C$3000,$B9,Preguntas!$G$2:$G$3000,"?*") -> 4 | I9: =COUNTIFS(Preguntas!$B$2:$B$3000,$A9,Preguntas!$C$2:$C$3000,$B9,Preguntas!$O$2:$O$3000,"Revisada") -> 0 | J9: =COUNTIFS(Preguntas!$B$2:$B$3000,$A9,Preguntas!$C$2:$C$3000,$B9,Preguntas!$P$2:$P$3000,"Sí") -> 12
A10: Frontend Angular | B10: Routing | C10: ang-routing | D10: =COUNTIFS(Preguntas!$B$2:$B$3000,$A10,Preguntas!$C$2:$C$3000,$B10,Preguntas!$D$2:$D$3000,"Junior") -> 4 | E10: =COUNTIFS(Preguntas!$B$2:$B$3000,$A10,Preguntas!$C$2:$C$3000,$B10,Preguntas!$D$2:$D$3000,"Mid") -> 4 | F10: =COUNTIFS(Preguntas!$B$2:$B$3000,$A10,Preguntas!$C$2:$C$3000,$B10,Preguntas!$D$2:$D$3000,"Senior") -> 4 | G10: =SUM(D10:F10) -> 12 | H10: =COUNTIFS(Preguntas!$B$2:$B$3000,$A10,Preguntas!$C$2:$C$3000,$B10,Preguntas!$G$2:$G$3000,"?*") -> 4 | I10: =COUNTIFS(Preguntas!$B$2:$B$3000,$A10,Preguntas!$C$2:$C$3000,$B10,Preguntas!$O$2:$O$3000,"Revisada") -> 0 | J10: =COUNTIFS(Preguntas!$B$2:$B$3000,$A10,Preguntas!$C$2:$C$3000,$B10,Preguntas!$P$2:$P$3000,"Sí") -> 12
A11: Frontend Angular | B11: Inyección de dependencias y HTTP | C11: ang-di-http | D11: =COUNTIFS(Preguntas!$B$2:$B$3000,$A11,Preguntas!$C$2:$C$3000,$B11,Preguntas!$D$2:$D$3000,"Junior") -> 4 | E11: =COUNTIFS(Preguntas!$B$2:$B$3000,$A11,Preguntas!$C$2:$C$3000,$B11,Preguntas!$D$2:$D$3000,"Mid") -> 4 | F11: =COUNTIFS(Preguntas!$B$2:$B$3000,$A11,Preguntas!$C$2:$C$3000,$B11,Preguntas!$D$2:$D$3000,"Senior") -> 4 | G11: =SUM(D11:F11) -> 12 | H11: =COUNTIFS(Preguntas!$B$2:$B$3000,$A11,Preguntas!$C$2:$C$3000,$B11,Preguntas!$G$2:$G$3000,"?*") -> 3 | I11: =COUNTIFS(Preguntas!$B$2:$B$3000,$A11,Preguntas!$C$2:$C$3000,$B11,Preguntas!$O$2:$O$3000,"Revisada") -> 0 | J11: =COUNTIFS(Preguntas!$B$2:$B$3000,$A11,Preguntas!$C$2:$C$3000,$B11,Preguntas!$P$2:$P$3000,"Sí") -> 12
A12: Frontend Angular | B12: Testing | C12: ang-testing | D12: =COUNTIFS(Preguntas!$B$2:$B$3000,$A12,Preguntas!$C$2:$C$3000,$B12,Preguntas!$D$2:$D$3000,"Junior") -> 4 | E12: =COUNTIFS(Preguntas!$B$2:$B$3000,$A12,Preguntas!$C$2:$C$3000,$B12,Preguntas!$D$2:$D$3000,"Mid") -> 4 | F12: =COUNTIFS(Preguntas!$B$2:$B$3000,$A12,Preguntas!$C$2:$C$3000,$B12,Preguntas!$D$2:$D$3000,"Senior") -> 4 | G12: =SUM(D12:F12) -> 12 | H12: =COUNTIFS(Preguntas!$B$2:$B$3000,$A12,Preguntas!$C$2:$C$3000,$B12,Preguntas!$G$2:$G$3000,"?*") -> 2 | I12: =COUNTIFS(Preguntas!$B$2:$B$3000,$A12,Preguntas!$C$2:$C$3000,$B12,Preguntas!$O$2:$O$3000,"Revisada") -> 0 | J12: =COUNTIFS(Preguntas!$B$2:$B$3000,$A12,Preguntas!$C$2:$C$3000,$B12,Preguntas!$P$2:$P$3000,"Sí") -> 12
A13: Frontend Angular | B13: Actualizaciones de versión e i18n | C13: ang-upgrade-i18n | D13: =COUNTIFS(Preguntas!$B$2:$B$3000,$A13,Preguntas!$C$2:$C$3000,$B13,Preguntas!$D$2:$D$3000,"Junior") -> 4 | E13: =COUNTIFS(Preguntas!$B$2:$B$3000,$A13,Preguntas!$C$2:$C$3000,$B13,Preguntas!$D$2:$D$3000,"Mid") -> 4 | F13: =COUNTIFS(Preguntas!$B$2:$B$3000,$A13,Preguntas!$C$2:$C$3000,$B13,Preguntas!$D$2:$D$3000,"Senior") -> 4 | G13: =SUM(D13:F13) -> 12 | H13: =COUNTIFS(Preguntas!$B$2:$B$3000,$A13,Preguntas!$C$2:$C$3000,$B13,Preguntas!$G$2:$G$3000,"?*") -> 2 | I13: =COUNTIFS(Preguntas!$B$2:$B$3000,$A13,Preguntas!$C$2:$C$3000,$B13,Preguntas!$O$2:$O$3000,"Revisada") -> 0 | J13: =COUNTIFS(Preguntas!$B$2:$B$3000,$A13,Preguntas!$C$2:$C$3000,$B13,Preguntas!$P$2:$P$3000,"Sí") -> 12
... A38: Desarrollo (todos los puestos técnicos) | B38: Docker a nivel usuario | C38: dev-docker | D38: =COUNTIFS(Preguntas!$B$2:$B$3000,$A38,Preguntas!$C$2:$C$3000,$B38,Preguntas!$D$2:$D$3000,"Junior") -> 4 | E38: =COUNTIFS(Preguntas!$B$2:$B$3000,$A38,Preguntas!$C$2:$C$3000,$B38,Preguntas!$D$2:$D$3000,"Mid") -> 4 | F38: =COUNTIFS(Preguntas!$B$2:$B$3000,$A38,Preguntas!$C$2:$C$3000,$B38,Preguntas!$D$2:$D$3000,"Senior") -> 4 | G38: =SUM(D38:F38) -> 12 | H38: =COUNTIFS(Preguntas!$B$2:$B$3000,$A38,Preguntas!$C$2:$C$3000,$B38,Preguntas!$G$2:$G$3000,"?*") -> 3 | I38: =COUNTIFS(Preguntas!$B$2:$B$3000,$A38,Preguntas!$C$2:$C$3000,$B38,Preguntas!$O$2:$O$3000,"Revisada") -> 0 | J38: =COUNTIFS(Preguntas!$B$2:$B$3000,$A38,Preguntas!$C$2:$C$3000,$B38,Preguntas!$P$2:$P$3000,"Sí") -> 12
A39: Total | D39: =SUM(D2:D38) -> 145 | E39: =SUM(E2:E38) -> 145 | F39: =SUM(F2:F38) -> 145 | G39: =SUM(G2:G38) -> 435 | H39: =SUM(H2:H38) -> 112 | I39: =SUM(I2:I38) -> 0 | J39: =SUM(J2:J38) -> 435

Sheet Preguntas
A1: ID | B1: Bloque | C1: Tema | D1: Nivel | E1: Tipo | F1: Pregunta (ES) | G1: Código | H1: Respuesta correcta | I1: Incorrecta 1 | J1: Incorrecta 2 | K1: Incorrecta 3 | L1: Explicación | M1: Frase ejemplo (EN) | N1: Traducción del ejemplo | O1: Estado | P1: Activa | Q1: Variante ES: pregunta | R1: Variante ES: correcta | S1: Variante ES: incorrectas (separadas por |) | T1: Variante ES: explicación
A2: com-star-J1 | B2: Común (todos los puestos) | C2: Presentación y método STAR | D2: Junior | E2: Elegir respuesta | F2: ¿Qué significa STAR? | H2: Situation, Task, Action, Result (Situación, Tarea, Acción, Resultado) | I2: Skills, Tools, Achievements, Results | J2: Situation, Team, Approach, Review | K2: Story, Task, Action, Reflection | L2: Es la estructura que esperan en las preguntas de comportamiento: "Tell me about a time when…". | O2: Pendiente de revisar | P2: Sí
A3: com-star-J2 | B3: Común (todos los puestos) | C3: Presentación y método STAR | D3: Junior | E3: Ordenar | F3: Ordena esta respuesta STAR | H3: En las prácticas, el formulario de registro tenía muchos abandonos. | Me pidieron averiguar por qué y proponer una mejora. | Analicé los errores de validación y simplifiqué el formulario de 9 a 5 campos. | Los registros completados subieron un 30% el mes siguiente. | L3: Situación → Tarea → Acción → Resultado. Cierra siempre con un resultado medible. | O3: Pendiente de revisar | P3: Sí
A4: com-star-J3 | B4: Común (todos los puestos) | C4: Presentación y método STAR | D4: Junior | E4: Elegir respuesta | F4: ¿Cuál es la mejor estructura para "Tell me about yourself"? | H4: Presente → pasado → futuro | I4: Infancia → estudios → aficiones | J4: Todo el CV, trabajo por trabajo | K4: Fortalezas → debilidades → salario | L4: Quién eres hoy, cómo llegaste y por qué este puesto encaja. Entre 60 y 90 segundos. | M4: I'm a junior developer who recently finished my training in web development. During my internship I worked on a real product with a team, which taught me a lot about code reviews and teamwork. Now I'm looking for a team where I can keep learning and start contributing from the first weeks. | N4: Soy desarrollador junior y acabo de terminar mi formación en desarrollo web. En las prácticas trabajé en un producto real con un equipo, lo que me enseñó mucho sobre code reviews y trabajo en equipo. Ahora busco un equipo donde seguir aprendiendo y empezar a aportar desde las primeras semanas. | O4: Pendiente de revisar | P4: Sí | Q4: ¿Cuál es la mejor estructura para responder a «Háblame de ti»?
A5: com-star-M1 | B5: Común (todos los puestos) | C5: Presentación y método STAR | D5: Mid | E5: Elegir respuesta | F5: ¿Qué respuesta a "What's your greatest weakness?" funciona mejor? | H5: I sometimes go too deep into details, so now I timebox research and check in with the team earlier. | I5: I'm a perfectionist and I work too hard. | J5: I don't really have weaknesses. | K5: I'm not very good at working in teams. | L5: Una debilidad real pero no crítica para el puesto, más lo que haces para mejorarla. | M5: Sometimes I go too deep into details before asking for help. Now I timebox my research, and if I'm stuck after an hour or so, I check in with the team. It's made me much faster. | N5: A veces profundizo demasiado en los detalles antes de pedir ayuda. Ahora me pongo un límite de tiempo y, si sigo atascado tras una hora, lo comento con el equipo. Me ha hecho mucho más rápido. | O5: Pendiente de revisar | P5: Sí | Q5: Te preguntan «¿Cuál es tu mayor debilidad?». ¿Qué respuesta funciona mejor? | R5: A veces profundizo demasiado en los detalles, así que ahora me pongo un límite de tiempo y consulto antes con el equipo. | S5: Soy perfeccionista y trabajo demasiado. | La verdad es que no tengo debilidades. | No se me da muy bien trabajar en equipo.
A6: com-star-M2 | B6: Común (todos los puestos) | C6: Presentación y método STAR | D6: Mid | E6: Elegir respuesta | F6: Te preguntan por un conflicto con un compañero. ¿Qué enfoque es mejor? | H6: Contar un desacuerdo real, cómo lo hablasteis con datos y cómo se resolvió, sin culpar a nadie | I6: Decir que nunca has tenido conflictos | J6: Explicar por qué el compañero estaba equivocado | K6: Cambiar de tema | L6: Buscan madurez: escuchar, argumentar con datos y priorizar el objetivo del equipo. | M6: In a project, a colleague and I disagreed about how to structure the state. Instead of arguing, we each wrote down pros and cons and built a quick proof of concept. We went with his approach, with one idea from mine, and it worked well. Since then we've worked really well together. | N6: En un proyecto, un compañero y yo no estábamos de acuerdo en cómo estructurar el estado. En vez de discutir, apuntamos pros y contras y montamos una prueba de concepto rápida. Elegimos su enfoque con una idea del mío y funcionó bien. Desde entonces trabajamos muy bien juntos. | O6: Pendiente de revisar | P6: Sí
A7: com-star-M3 | B7: Común (todos los puestos) | C7: Presentación y método STAR | D7: Mid | E7: Completar frase | F7: En una respuesta STAR, habla de lo que hiciste ___, no solo de lo que hizo el equipo. | H7: tú | I7: el jefe | J7: el cliente | K7: la empresa | L7: Di "I" más que "we": quieren saber cuál fue tu aportación. | O7: Pendiente de revisar | P7: Sí | T7: Habla en primera persona («yo propuse», «yo implementé») más que en plural: quieren saber cuál fue tu aportación.
A8: com-star-S1 | B8: Común (todos los puestos) | C8: Presentación y método STAR | D8: Senior | E8: Elegir respuesta | F8: Te preguntan cómo has ayudado a crecer a otras personas. ¿Qué incluyes? | H8: Un ejemplo concreto de mentoring con acciones (pair programming, feedback, delegar retos) y su resultado | I8: Que siempre ayudas cuando te preguntan | J8: Que el crecimiento es responsabilidad de cada uno | K8: Una lista de cursos que recomiendas | L8: En perfiles senior buscan impacto en el equipo, no solo en el código. | M8: I mentored a junior developer who was struggling with RxJS. We did pair programming twice a week, I gave her small but real tasks, and I reviewed her pull requests with explanations, not just corrections. After three months she was leading a feature on her own. | N8: Fui mentor de una desarrolladora junior a la que le costaba RxJS. Hacíamos pair programming dos veces por semana, le daba tareas pequeñas pero reales y revisaba sus pull requests explicando, no solo corrigiendo. A los tres meses lideraba ella sola una funcionalidad. | O8: Pendiente de revisar | P8: Sí
A9: com-star-S2 | B9: Común (todos los puestos) | C9: Presentación y método STAR | D9: Senior | E9: Elegir respuesta | F9: ¿Cómo respondes a "Tell me about a technical decision you regret"? | H9: Con una decisión real, por qué tenía sentido entonces, qué aprendiste y qué harías distinto | I9: Diciendo que nunca te arrepientes de nada | J9: Culpando al equipo de producto | K9: Con un error trivial sin consecuencias | L9: Demuestra criterio y capacidad de aprender, que es lo que se espera de un senior. | M9: We added a global state library very early in a project, when the app was still small. It slowed the team down with a lot of boilerplate. Now I start with the simplest option and only add complexity when there's a clear need. | N9: Añadimos una librería de estado global muy pronto en un proyecto, cuando la app aún era pequeña. Ralentizó al equipo con mucho código repetitivo. Ahora empiezo por la opción más sencilla y solo añado complejidad cuando hay una necesidad clara. | O9: Pendiente de revisar | P9: Sí | Q9: ¿Cómo respondes a «Cuéntame una decisión técnica de la que te arrepientas»?
A10: com-star-S3 | B10: Común (todos los puestos) | C10: Presentación y método STAR | D10: Senior | E10: Completar frase | F10: Para un senior, una buena respuesta STAR muestra el impacto en el ___, no solo en el código. | H10: negocio | I10: framework | J10: IDE | K10: linter | L10: Habla de usuarios, costes, tiempos de entrega o ventas cuando puedas. | O10: Pendiente de revisar | P10: Sí
A11: com-dificiles-J1 | B11: Común (todos los puestos) | C11: Preguntas difíciles | D11: Junior | E11: Elegir respuesta | F11: "Why should we hire you?" (¿por qué deberíamos contratarte?) ¿Qué enfoque es mejor? | H11: Unir dos o tres cosas concretas tuyas con lo que pide la oferta, y tu ganas de aprender | I11: Decir que necesitas el trabajo | J11: Decir que eres el mejor candidato sin más | K11: Hablar de lo que no te gusta de tu trabajo actual | L11: Relaciona tus fortalezas con las necesidades del puesto. | M11: You're looking for someone who knows Angular and can learn fast. I've built two projects with Angular and TypeScript, I'm used to working with Git in a team from my internship, and I'm someone who asks questions and learns quickly. | N11: Buscáis a alguien que conozca Angular y aprenda rápido. He hecho dos proyectos con Angular y TypeScript, estoy acostumbrado a trabajar con Git en equipo desde las prácticas y soy alguien que pregunta y aprende rápido. | O11: Pendiente de revisar | P11: Sí | Q11: «¿Por qué deberíamos contratarte?» ¿Qué enfoque es mejor?
A12: com-dificiles-J2 | B12: Común (todos los puestos) | C12: Preguntas difíciles | D12: Junior | E12: Elegir respuesta | F12: Te preguntan algo técnico que no sabes. ¿Qué haces? | H12: Reconocerlo con naturalidad, explicar cómo lo averiguarías o razonar en voz alta lo que sí sabes | I12: Inventarte la respuesta | J12: Quedarte en silencio | K12: Decir que no es importante | L12: Inventar se nota y resta mucho; razonar suma. | M12: I haven't worked with that directly, but I'd guess it works similarly to X. In a real situation, I'd check the official documentation and try a small example. | N12: No he trabajado con eso directamente, pero imagino que funciona de forma parecida a X. En una situación real, miraría la documentación oficial y probaría con un ejemplo pequeño. | O12: Pendiente de revisar | P12: Sí
A13: com-dificiles-J3 | B13: Común (todos los puestos) | C13: Preguntas difíciles | D13: Junior | E13: Elegir respuesta | F13: ¿Qué buena pregunta puedes hacer tú al final? | H13: What does a typical day look like for someone in this role? | I13: How many vacation days do I get? | J13: So, what does your company do? | K13: No, I don't have any questions. | L13: Demuestra interés real y te da información para decidir. | M13: What does a typical day look like for someone in this role? And how do new people get support during their first months? | N13: ¿Cómo es un día normal en este puesto? ¿Y cómo apoyáis a las personas nuevas durante los primeros meses? | O13: Pendiente de revisar | P13: Sí | R13: ¿Cómo es un día normal para alguien en este puesto? | S13: ¿Cuántos días de vacaciones tendría? | Entonces, ¿a qué se dedica vuestra empresa? | No, no tengo ninguna pregunta.
A14: com-dificiles-M1 | B14: Común (todos los puestos) | C14: Preguntas difíciles | D14: Mid | E14: Elegir respuesta | F14: "I see a gap in your recent experience." (veo un hueco en tu experiencia reciente) ¿Cómo lo enfocas? | H14: Breve y sincero, y luego centrarte en lo que hiciste para seguir en forma y por qué estás listo ahora | I14: Cambiar de tema rápido | J14: Explicar con detalle todo lo que salió mal | K14: Echar la culpa a tu anterior empresa | L14: Una frase de contexto, sin dramas, y enseguida a lo positivo. | M14: Yes, my last project had very little development work, so I decided to use that time to retrain. I've been learning new technologies and catching up with the latest versions of my stack. Now I'm really keen to get back into a team and build things. | N14: Sí, mi último proyecto tenía muy poco desarrollo, así que decidí aprovechar ese tiempo para formarme. He estado aprendiendo tecnologías nuevas y poniéndome al día con las últimas versiones de mi stack. Ahora tengo muchas ganas de volver a un equipo y construir cosas. | O14: Pendiente de revisar | P14: Sí | Q14: «Veo un hueco en tu experiencia reciente.» ¿Cómo lo enfocas?
A15: com-dificiles-M2 | B15: Común (todos los puestos) | C15: Preguntas difíciles | D15: Mid | E15: Elegir respuesta | F15: "Why did you leave your last job?" (¿por qué dejaste tu último trabajo?) ¿Qué respondes? | H15: I wanted more hands-on coding and growth, and that wasn't possible on that project. | I15: My manager was terrible. | J15: Honestly, I just needed any job. | K15: I got bored. | L15: Nunca hables mal de una empresa anterior. Enmárcalo en lo que buscas, no en lo que huyes. | M15: I was on a project where I wasn't getting much hands-on development, and I want to keep growing as a developer. So I'm looking for a team where I can build features every day and learn from good engineers. | N15: Estaba en un proyecto donde apenas hacía desarrollo, y quiero seguir creciendo como desarrollador. Por eso busco un equipo donde pueda construir funcionalidades cada día y aprender de buenos ingenieros. | O15: Pendiente de revisar | P15: Sí | Q15: «¿Por qué dejaste tu último trabajo?» ¿Qué respondes? | R15: Quería programar más y seguir creciendo, y en ese proyecto no era posible. | S15: Mi jefe era horrible. | Sinceramente, necesitaba cualquier trabajo. | Me aburría.
A16: com-dificiles-M3 | B16: Común (todos los puestos) | C16: Preguntas difíciles | D16: Mid | E16: Elegir respuesta | F16: "What are your salary expectations?" (¿qué expectativas salariales tienes?) ¿Cómo lo enfocas? | H16: Dar un rango investigado para el puesto y la ciudad, y mostrar algo de flexibilidad | I16: Decir "lo que os parezca justo" | J16: Negarte a responder | K16: Decir una cifra muy por encima del mercado | L16: Un rango investigado te protege de pedir poco y no cierra la puerta. | M16: Based on what I've seen for similar roles, I'm looking for something between X and Y a year. But I'm flexible, it depends on the whole package and the remote options. | N16: Por lo que he visto en puestos similares, busco algo entre X e Y al año. Pero soy flexible: depende del paquete completo y de las opciones de teletrabajo. (Sustituye X e Y por tu rango real.) | O16: Pendiente de revisar | P16: Sí | Q16: «¿Qué expectativas salariales tienes?» ¿Cómo lo enfocas?
A17: com-dificiles-S1 | B17: Común (todos los puestos) | C17: Preguntas difíciles | D17: Senior | E17: Elegir respuesta | F17: Tienes otra oferta y te preguntan si estás en otros procesos. ¿Qué haces? | H17: Ser sincero sin dar detalles innecesarios, y dejar claro por qué te interesa especialmente este puesto | I17: Mentir y decir que no | J17: Usarlo para presionar de forma agresiva | K17: Negarte a responder | L17: La transparencia genera confianza y puede acelerar el proceso. | M17: Yes, I'm in a couple of other processes, one of them at an advanced stage. But this role is my first choice because of the product and the team, so I'd be happy to move forward quickly if it works for you. | N17: Sí, estoy en un par de procesos más, uno de ellos bastante avanzado. Pero este puesto es mi primera opción por el producto y el equipo, así que me encantaría avanzar rápido si os encaja. | O17: Pendiente de revisar | P17: Sí
A18: com-dificiles-S2 | B18: Común (todos los puestos) | C18: Preguntas difíciles | D18: Senior | E18: Elegir respuesta | F18: "How do you handle disagreement with your manager about a technical decision?" ¿Qué enfoque es mejor? | H18: Plantear tu postura con datos y riesgos, escuchar sus motivos y, si se decide lo contrario, comprometerte con la decisión | I18: Hacer lo que tú crees sin decir nada | J18: Escalar directamente a su jefe | K18: Aceptar siempre sin opinar | L18: Es el principio de "disagree and commit". | M18: I'd explain my concerns with data, for example the risks or the cost of each option, and listen to the reasons behind the decision. If we still go another way, I commit to it fully, and we agree on a point to review whether it's working. | N18: Explicaría mis dudas con datos, por ejemplo los riesgos o el coste de cada opción, y escucharía los motivos de la decisión. Si aun así se elige otro camino, me comprometo del todo y acordamos un momento para revisar si está funcionando. | O18: Pendiente de revisar | P18: Sí | Q18: «¿Cómo gestionas un desacuerdo con tu responsable sobre una decisión técnica?» ¿Qué enfoque es mejor?
A19: com-dificiles-S3 | B19: Común (todos los puestos) | C19: Preguntas difíciles | D19: Senior | E19: Elegir respuesta | F19: "Why are you looking for a change after so many years?" ¿Qué respuesta funciona mejor? | H19: Hablar de lo que buscas ahora (impacto, retos, liderazgo) y por qué este puesto lo ofrece | I19: Decir que estás quemado | J19: Quejarte de tu empresa actual | K19: Decir que es solo por dinero | L19: Enfoque positivo y orientado al futuro. | M19: I've learned a lot in my current company, but I feel I've reached a point where I want a bigger impact, for example shaping the architecture of a product from the start. This role offers exactly that. | N19: He aprendido mucho en mi empresa actual, pero siento que he llegado a un punto en el que quiero más impacto, por ejemplo definir la arquitectura de un producto desde el principio. Este puesto me ofrece justo eso. | O19: Pendiente de revisar | P19: Sí | Q19: «¿Por qué buscas un cambio después de tantos años?» ¿Qué respuesta funciona mejor?
A20: com-ingles-J1 | B20: Común (todos los puestos) | C20: Inglés de entrevista | D20: Junior | E20: Elegir respuesta | F20: "Actualmente trabajo con Angular" → | H20: I'm currently working with Angular. | I20: Actually I work with Angular. | J20: Actually I'm working in Angular. | K20: In the actual moment I work with Angular. | L20: Actually = en realidad. Actualmente = currently / at the moment. | O20: Pendiente de revisar | P20: Sí
A21: com-ingles-J2 | B21: Común (todos los puestos) | C21: Inglés de entrevista | D21: Junior | E21: Completar frase | F21: I've been working with Angular ___ 2019. | H21: since | I21: for | J21: from | K21: during | L21: Since + punto de inicio (since 2019). For + duración (for five years). | O21: Pendiente de revisar | P21: Sí
A22: com-ingles-J3 | B22: Común (todos los puestos) | C22: Inglés de entrevista | D22: Junior | E22: Elegir respuesta | F22: No has entendido la pregunta. Dices: | H22: Sorry, could you rephrase that, please? | I22: What? | J22: Repeat. | K22: I no understand. | L22: Pedir que lo reformulen es normal y profesional. | M22: Sorry, could you rephrase that, please? Just to make sure: do you mean how I would build it, or how I would test it? | N22: Perdona, ¿podrías reformularlo? Solo para asegurarme: ¿te refieres a cómo lo construiría o a cómo lo testearía? | O22: Pendiente de revisar | P22: Sí
A23: com-ingles-M1 | B23: Común (todos los puestos) | C23: Inglés de entrevista | D23: Mid | E23: Elegir respuesta | F23: "Asistí a la reunión de planificación" → | H23: I attended the planning meeting. | I23: I assisted the planning meeting. | J23: I assisted to the planning meeting. | K23: I went in the planning meeting. | L23: Attend = asistir (estar presente). Assist = ayudar. | O23: Pendiente de revisar | P23: Sí
A24: com-ingles-M2 | B24: Común (todos los puestos) | C24: Inglés de entrevista | D24: Mid | E24: Elegir respuesta | F24: "Me encargaba del módulo de pagos" → | H24: I was in charge of the payments module. | I24: I was charged of the payments module. | J24: I encharged the payments module. | K24: I was encharged of the payments module. | L24: In charge of / responsible for. "Charge" a secas es cobrar o cargar. | O24: Pendiente de revisar | P24: Sí
A25: com-ingles-M3 | B25: Común (todos los puestos) | C25: Inglés de entrevista | D25: Mid | E25: Elegir respuesta | F25: Necesitas unos segundos para pensar. ¿Qué frase es la mejor? | H25: That's a good question. Let me think about it for a second. | I25: Eh… eh… wait. | J25: I don't know. | K25: Next question, please. | L25: Pensar en voz alta está bien visto en entrevistas técnicas. | M25: That's a good question. Let me think about it for a second… OK, so the way I see it is… | N25: Buena pregunta. Déjame pensarlo un segundo… Vale, tal y como yo lo veo… | O25: Pendiente de revisar | P25: Sí
A26: com-ingles-S1 | B26: Común (todos los puestos) | C26: Inglés de entrevista | D26: Senior | E26: Elegir respuesta | F26: Para matizar una opinión de forma profesional, ¿qué frase suena mejor? | H26: I see your point, but I'd push back a little on that, because… | I26: You're wrong. | J26: No, no, no. | K26: That's a stupid idea. | L26: En inglés profesional se suaviza el desacuerdo: "I'd push back a bit", "I see it slightly differently". | M26: I see your point, but I'd push back a little on that, because in my experience it adds complexity we don't need yet. | N26: Entiendo lo que dices, pero no estoy del todo de acuerdo, porque en mi experiencia añade una complejidad que todavía no necesitamos. | O26: Pendiente de revisar | P26: Sí
A27: com-ingles-S2 | B27: Común (todos los puestos) | C27: Inglés de entrevista | D27: Senior | E27: Elegir respuesta | F27: "Llevé a cabo la migración" → | H27: I led / carried out the migration. | I27: I realized the migration. | J27: I made the migration realized. | K27: I carried the migration. | L27: Realize = darse cuenta. Para "realizar" usa carry out, do, lead o implement. | O27: Pendiente de revisar | P27: Sí
A28: com-ingles-S3 | B28: Común (todos los puestos) | C28: Inglés de entrevista | D28: Senior | E28: Completar frase | F28: If I ___ known about the issue earlier, I would have fixed it before the release. | H28: had | I28: have | J28: would | K28: was | L28: Tercer condicional: If + had + participio, would have + participio. | O28: Pendiente de revisar | P28: Sí
A29: ang-components-J1 | B29: Frontend Angular | C29: Componentes y plantillas | D29: Junior | E29: Elegir respuesta | F29: Pulsas el botón tres veces. ¿Qué muestra? | G29: @Component({ selector: 'app-counter', template: `<button (click)="inc()">{{ count() }}</button>`, }) export class Counter { count = signal(0); inc() { this.count.update(c => c + 1); } } | H29: 3 | I29: 0, porque las signals no se actualizan en la plantilla | J29: Un error: falta standalone: true | K29: count() | L29: update() recibe el valor actual y devuelve el nuevo. En Angular reciente los componentes son standalone por defecto. | O29: Pendiente de revisar | P29: Sí
A30: ang-components-J2 | B30: Frontend Angular | C30: Componentes y plantillas | D30: Junior | E30: Elegir respuesta | F30: ¿Qué tipo de binding es `[disabled]="isSaving"`? | H30: Property binding (del componente a la vista) | I30: Event binding (de la vista al componente) | J30: Two-way binding | K30: Interpolación | L30: Los corchetes enlazan una propiedad del DOM con un valor del componente. Los paréntesis son eventos y `[( )]` es two-way. | O30: Pendiente de revisar | P30: Sí
A31: ang-components-J3 | B31: Frontend Angular | C31: Componentes y plantillas | D31: Junior | E31: Completar frase | F31: Para que un hijo emita eventos al padre se declara `saved = ___<Item>();` | H31: output | I31: input | J31: signal | K31: model | L31: `output()` crea el emisor; el padre escucha con `(saved)="onSaved($event)"`. Con decoradores sería `@Output()` y un EventEmitter. | O31: Pendiente de revisar | P31: Sí
A32: ang-components-J4 | B32: Frontend Angular | C32: Componentes y plantillas | D32: Junior | E32: Elegir respuesta | F32: Si `user()` devuelve null, ¿qué se pinta? | G32: @if (user(); as u) { <p>Hola, {{ u.name }}</p> } @else { <p>Inicia sesión</p> } | H32: Inicia sesión | I32: Hola, | J32: Nada | K32: Un error en consola | L32: `@if` evalúa la condición: con null pasa al bloque `@else`. El alias `as u` solo existe dentro del bloque `@if`. | O32: Pendiente de revisar | P32: Sí
A33: ang-components-M1 | B33: Frontend Angular | C33: Componentes y plantillas | D33: Mid | E33: Elegir respuesta | F33: ¿Qué falta para que compile este bucle? | G33: @for (item of items()) { <li>{{ item.name }}</li> } | H33: `track`, por ejemplo `track item.id`: es obligatorio en `@for` | I33: Un `*ngFor` en el elemento padre | J33: Declarar `let i = index` | K33: Nada, compila tal cual | L33: En el control flow integrado `track` es obligatorio. Con un identificador estable, Angular reutiliza los elementos del DOM. | O33: Pendiente de revisar | P33: Sí
A34: ang-components-M2 | B34: Frontend Angular | C34: Componentes y plantillas | D34: Mid | E34: Elegir respuesta | F34: ¿Dónde aparece el `<p>`? | G34: <!-- card.html --> <header><ng-content select="[card-title]" /></header> <ng-content /> <!-- uso --> <app-card> <h2 card-title>Título</h2> <p>Texto</p> </app-card> | H34: En el `<ng-content />` sin selector, debajo del header | I34: Dentro del header | J34: En ningún sitio: solo se proyecta lo que coincide con un selector | K34: Duplicado en los dos huecos | L34: Lo que coincide con `select` va a ese hueco; el resto va al `<ng-content />` sin selector. | O34: Pendiente de revisar | P34: Sí
A35: ang-components-M3 | B35: Frontend Angular | C35: Componentes y plantillas | D35: Mid | E35: Elegir respuesta | F35: El padre usa `<app-user />` sin pasar `[name]`. ¿Qué ocurre? | G35: export class UserCard { name = input.required<string>(); } | H35: Error de compilación: el input es obligatorio | I35: `name()` devuelve undefined | J35: `name()` devuelve una cadena vacía | K35: Error solo en ejecución al leerlo | L35: `input.required` obliga al padre a enlazarlo; el compilador de plantillas lo comprueba. | O35: Pendiente de revisar | P35: Sí
A36: ang-components-M4 | B36: Frontend Angular | C36: Componentes y plantillas | D36: Mid | E36: Elegir respuesta | F36: ¿Qué permite `model()`? | G36: // hijo value = model(0); increment() { this.value.update(v => v + 1); } // padre <app-stepper [(value)]="qty" /> | H36: Two-way binding: el hijo puede hacer `value.set()` y el padre recibe el cambio | I36: Solo leer el valor del padre | J36: Crear un formulario reactivo | K36: Compartir estado global | L36: `model()` es un input escribible. El padre lo enlaza con `[(value)]`. | O36: Pendiente de revisar | P36: Sí
A37: ang-components-S1 | B37: Frontend Angular | C37: Componentes y plantillas | D37: Senior | E37: Elegir respuesta | F37: ¿Diferencia entre `viewChild()` y `contentChild()`? | H37: viewChild busca en la plantilla propia del componente; contentChild en el contenido proyectado por el padre | I37: Son sinónimos | J37: contentChild solo funciona con directivas | K37: viewChild solo funciona tras ngOnDestroy | L37: La vista es lo que declara tu plantilla; el contenido es lo que el padre mete entre tus etiquetas. | O37: Pendiente de revisar | P37: Sí
A38: ang-components-S2 | B38: Frontend Angular | C38: Componentes y plantillas | D38: Senior | E38: Elegir respuesta | F38: ¿Para qué sirve `hostDirectives` en un componente? | H38: Aplicar directivas standalone al elemento host por composición, sin herencia | I38: Inyectar servicios en el host | J38: Crear rutas hijas | K38: Cambiar el selector en tiempo de ejecución | L38: Permite reutilizar comportamiento (tooltip, focus, a11y) componiéndolo, en lugar de heredar de clases base. | O38: Pendiente de revisar | P38: Sí
A39: ang-components-S3 | B39: Frontend Angular | C39: Componentes y plantillas | D39: Senior | E39: Elegir respuesta | F39: ¿Por qué usar `setInput` en lugar de `ref.instance.message = ...`? | G39: private vcr = inject(ViewContainerRef); open() { const ref = this.vcr.createComponent(AlertComponent); ref.setInput('message', 'Guardado'); } | H39: Actualiza el input a través de Angular: funciona con `input()` signals y marca el componente para revisión | I39: Es más rápido de escribir | J39: Porque instance no existe | K39: No hay diferencia | L39: Con inputs basados en signals no puedes asignar directamente; `setInput` además dispara la detección de cambios correcta. | O39: Pendiente de revisar | P39: Sí
A40: ang-components-S4 | B40: Frontend Angular | C40: Componentes y plantillas | D40: Senior | E40: Elegir respuesta | F40: Con `ViewEncapsulation.Emulated` (por defecto), ¿cómo se aíslan los estilos? | H40: Angular añade atributos únicos (`_ngcontent-…`) a los elementos y reescribe los selectores | I40: Usa Shadow DOM real | J40: No se aíslan | K40: Prefija las clases con el nombre del componente | L40: Por eso un estilo de un componente no afecta a otros. `ShadowDom` sí usa Shadow DOM nativo, y `None` hace los estilos globales. | O40: Pendiente de revisar | P40: Sí
...
